2021-10-17 23:22:11,633  ERROR       client  [Errno 61] Connection refused
Traceback (most recent call last):
  File "client.py", line 35, in connect
    self.client.connect((address, port))  # подключение
ConnectionRefusedError: [Errno 61] Connection refused
2021-10-17 23:22:11,633  ERROR       client  Отправка сообщения невозможна, соединение с сервером небыло установленно.
2021-10-17 23:22:17,680  INFO        client  Установлено соединение с сервером.
2021-10-17 23:22:17,681  INFO        client  Отправлено сообщение: '{'action': 'presence', 'time': 1634502137, 'type': 'status', 'user': {'account_name': 'Klark Charlz', 'status': 'Online'}}'.
2021-10-17 23:22:17,682  INFO        client  Получено сообщение: '{'alert': 'OK', 'response': 200}'.
